<?xml version="1.0" encoding="UTF-8"?>
<!-- Generated by org.testng.reporters.JUnitXMLReporter -->
<testsuite ignored="0" hostname="hello-world" failures="1" tests="6" name="Default test" time="0.08" errors="0" timestamp="06 Jun 2020 05:02:25 GMT">
  <testcase classname="TestCalculator" name="addThreeNUmberWithDelimeterReturnSum" time="0.012"/>
  <testcase classname="TestCalculator" name="emptyStringReturnZero" time="0.002"/>
  <testcase classname="TestCalculator" name="negativeException" time="0.002">
    <failure type="org.testng.TestException" message="
Method TestCalculator.negativeException()[pri:0, instance:TestCalculator@770c2e6b] should have thrown an exception of type class java.lang.Exception">
      <![CDATA[org.testng.TestException: 
Method TestCalculator.negativeException()[pri:0, instance:TestCalculator@770c2e6b] should have thrown an exception of type class java.lang.Exception
at org.testng.internal.ExpectedExceptionsHolder.noException(ExpectedExceptionsHolder.java:80)
at org.testng.internal.Invoker.considerExceptions(Invoker.java:1140)
at org.testng.internal.Invoker.invokeMethod(Invoker.java:615)
at org.testng.internal.Invoker.invokeTestMethod(Invoker.java:719)
at org.testng.internal.Invoker.invokeTestMethods(Invoker.java:989)
at org.testng.internal.TestMethodWorker.invokeTestMethods(TestMethodWorker.java:125)
at org.testng.internal.TestMethodWorker.run(TestMethodWorker.java:109)
at org.testng.TestRunner.privateRun(TestRunner.java:648)
at org.testng.TestRunner.run(TestRunner.java:505)
at org.testng.SuiteRunner.runTest(SuiteRunner.java:455)
at org.testng.SuiteRunner.runSequentially(SuiteRunner.java:450)
at org.testng.SuiteRunner.privateRun(SuiteRunner.java:415)
at org.testng.SuiteRunner.run(SuiteRunner.java:364)
at org.testng.SuiteRunnerWorker.runSuite(SuiteRunnerWorker.java:52)
at org.testng.SuiteRunnerWorker.run(SuiteRunnerWorker.java:84)
at org.testng.TestNG.runSuitesSequentially(TestNG.java:1208)
at org.testng.TestNG.runSuitesLocally(TestNG.java:1137)
at org.testng.TestNG.runSuites(TestNG.java:1049)
at org.testng.TestNG.run(TestNG.java:1017)
at org.testng.remote.AbstractRemoteTestNG.run(AbstractRemoteTestNG.java:115)
at org.testng.remote.RemoteTestNG.initAndRun(RemoteTestNG.java:251)
at org.testng.remote.RemoteTestNG.main(RemoteTestNG.java:77)
]]>
    </failure>
  </testcase> <!-- negativeException -->
  <testcase classname="TestCalculator" name="singleValueReply" time="0.001"/>
  <testcase classname="TestCalculator" name="twoNumbersCommaDelimeterReturnSum" time="0.001"/>
  <testcase classname="TestCalculator" name="twonumbersLinechnageDelimeterReturnsum" time="0.001"/>
</testsuite> <!-- Default test -->
